my custon<?xml version="1.0" ?> <!--xml declaration-->
<robot name="turtlebot3_burger" xmlns:xacro="http://ros.org/wiki/xacro"> <!--root tag-->
  <xacro:include filename="$(find turtlebot3_description)/urdf/common_properties.xacro"/> <!--include common_properties.xacro-->
  <xacro:include filename="$(find turtlebot3_description)/urdf/turtlebot3_burger.gazebo.xacro"/> <!--include turtlebot3_burger.gazebo.xacro-->
  <xacro:include filename="$(find turtlebot3_description)/urdf/_d435.urdf.xacro"/> <!--include _d435.urdf.xacro-->
    
<!--List of Links:
base_footprint
base_link
wheel_left_link
wheel_right_link
caster_back_link
imu_link
base_scan_link-->

<!--List of Joints:
base_joint
wheel_left_joint
wheel_right_joint
caster_back_joint
imu_joint
scan_joint-->

  <link name="base_footprint"/> <!--base_footprint_link start-->
  </link> <!--base_footprint_link end-->

  <joint name="base_joint" type="fixed"> <!--base_joint start-->
    <parent link="base_footprint"/>
    <child link="base_link"/> <!--defines the location of the child link with respect to the parent link-->
    <origin xyz="0.0 0.0 0.010" rpy="0 0 0"/> <!--reelation of the two links before motion is applied-->
  </joint> <!--base_joint end-->

  <link name="base_link"> <!--base_link start-->
    <visual> <!--visual property start-->
      <origin xyz="-0.032 0 0.0" rpy="0 0 0"/> <!--offset-->
      <geometry> <!--shape--> 
        <mesh filename="package://turtlebot3_description/meshes/bases/burger_base.stl" scale="0.001 0.001 0.001"/>
      </geometry>
      <material name="light_black"/> <!--colort-->
    </visual> <!--visual property end-->

    <collision> <!--collision property start-->
      <origin xyz="-0.032 0 0.070" rpy="0 0 0"/> <!--offset-->
      <geometry> <!--shape--> 
        <box size="0.140 0.140 0.143"/>
      </geometry>
    </collision> <!--collision property end-->

    <inertial> <!--inertial property start (how the link responds to forces)-->
      <origin xyz="0 0 0" rpy="0 0 0"/> <!--center of mass-->
      <mass value="8.2573504e-01"/> <!--mass-->
      <!-- rotational inertia matrix -->
      <inertia ixx="2.2124416e-03" ixy="-1.2294101e-05" ixz="3.4938785e-05" 
               iyy="2.1193702e-03" iyz="-5.0120904e-06"
               izz="2.0064271e-03" />
    </inertial> <!--inertial property end-->
  </link> <!--base_link end-->

  <joint name="wheel_left_joint" type="continuous"> <!--wheel_left_joint start-->
    <parent link="base_link"/>
    <child link="wheel_left_link"/>
    <origin xyz="0.0 0.08 0.023" rpy="-1.57 0 0"/>
    <axis xyz="0 0 1"/> <!--define the axis that the join moves around-->
  </joint> <!--wheel_left_joint end-->

  <link name="wheel_left_link"> <!--wheel_left_link start-->
    <visual>
      <origin xyz="0 0 0" rpy="1.57 0 0"/>
      <geometry>
        <mesh filename="package://turtlebot3_description/meshes/wheels/left_tire.stl" scale="0.001 0.001 0.001"/>
      </geometry>
      <material name="dark"/>
    </visual>

    <collision>
      <origin xyz="0 0 0" rpy="0 0 0"/>
      <geometry>
        <cylinder length="0.018" radius="0.033"/>
      </geometry>
    </collision>

    <inertial>
      <origin xyz="0 0 0" />
      <mass value="2.8498940e-02" />
      <inertia ixx="1.1175580e-05" ixy="-4.2369783e-11" ixz="-5.9381719e-09"
               iyy="1.1192413e-05" iyz="-1.4400107e-11"
               izz="2.0712558e-05" />
      </inertial>
  </link> <!--wheel_left_link end-->

  <joint name="wheel_right_joint" type="continuous"> <!--wheel_right_joint start-->
    <parent link="base_link"/>
    <child link="wheel_right_link"/>
    <origin xyz="0.0 -0.080 0.023" rpy="-1.57 0 0"/>
    <axis xyz="0 0 1"/>
  </joint> <!--wheel_right_joint end-->

  <link name="wheel_right_link"> <!--wheel_right_link start-->
    <visual>
      <origin xyz="0 0 0" rpy="1.57 0 0"/>
      <geometry>
        <mesh filename="package://turtlebot3_description/meshes/wheels/right_tire.stl" scale="0.001 0.001 0.001"/>
      </geometry>
      <material name="dark"/>
    </visual>

    <collision>
      <origin xyz="0 0 0" rpy="0 0 0"/>
      <geometry>
        <cylinder length="0.018" radius="0.033"/>
      </geometry>
    </collision>

    <inertial>
      <origin xyz="0 0 0" />
      <mass value="2.8498940e-02" />
      <inertia ixx="1.1175580e-05" ixy="-4.2369783e-11" ixz="-5.9381719e-09"
               iyy="1.1192413e-05" iyz="-1.4400107e-11"
               izz="2.0712558e-05" />
      </inertial>
  </link> <!--wheel_right_link end-->

  <joint name="caster_back_joint" type="fixed"> <!--caster_back_joint start-->
    <parent link="base_link"/>
    <child link="caster_back_link"/>
    <origin xyz="-0.081 0 -0.004" rpy="-1.57 0 0"/>
  </joint>

  <link name="caster_back_link"> <!--caster_back_link start-->
    <collision>
      <origin xyz="0 0.001 0" rpy="0 0 0"/>
      <geometry>
        <box size="0.030 0.009 0.020"/>
      </geometry>
    </collision>

    <inertial>
      <origin xyz="0 0 0" />
      <mass value="0.005" />
      <inertia ixx="0.001" ixy="0.0" ixz="0.0"
               iyy="0.001" iyz="0.0"
               izz="0.001" />
    </inertial>
  </link> <!--caster_back_link end-->

  <joint name="imu_joint" type="fixed"> <!--imu_joint start-->
    <parent link="base_link"/>
    <child link="imu_link"/>
    <origin xyz="-0.032 0 0.068" rpy="0 0 0"/>
  </joint> <!--imu_joint end-->

  <link name="imu_link"/> <!--imu_link start-->
  </link> <!--imu_link end-->

  <joint name="scan_joint" type="fixed"> <!--scan_joint start-->
    <parent link="base_link"/>
    <child link="base_scan"/>
    <origin xyz="-0.032 0 0.172" rpy="0 0 0"/>
  </joint> <!--scan_joint end-->

  <link name="base_scan"> <!--base_scan_link start-->
    <visual>
      <origin xyz="0 0 0.0" rpy="0 0 0"/>
      <geometry>
        <mesh filename="package://turtlebot3_description/meshes/sensors/lds.stl" scale="0.001 0.001 0.001"/>
      </geometry>
      <material name="dark"/>
    </visual>

    <collision>
      <origin xyz="0.015 0 -0.0065" rpy="0 0 0"/>
      <geometry>
        <cylinder length="0.0315" radius="0.055"/>
      </geometry>
    </collision>

    <inertial>
      <mass value="0.114" />
      <origin xyz="0 0 0" />
      <inertia ixx="0.001" ixy="0.0" ixz="0.0"
               iyy="0.001" iyz="0.0"
               izz="0.001" />
    </inertial>
  </link> <!--base_scan_link end-->

  <joint name="d435_joint" type="fixed"> <!--d435_joint start-->
    <parent link="base_link"/>
    <child link="sensor_d435"/>
    <origin xyz="0.015 0 0.085" rpy="0 0 0"/>
  </joint> <!--scan_joint end-->

</robot> <!--END-->
